Workbook
Name FarmName: LISTS!$B$6
Name ExpiryWarnDays: LISTS!$B$7
Name L_FeedTypes: tFeedTypes[[Feed Type]]
Name L_Drugs: tDrugs[[Drug Name]]
Name L_Units: tUnits[[Unit]]
Name L_Animals: tAnimalTypes[[Animal Type]]
Name L_Products: tProducts[[Product]]
Name L_ExpCat: tExpCat[[Expense Category]]
Name L_Pay: tPayMethods[[Payment Method]]
Name L_Causes: tCauses[[Mortality Cause]]
Name L_Meas: tMeasTypes[[Measurement Type]]
Name L_Reasons: tDrugReasons[[Drug Reason]]
Name L_MoveTypes: tMoveTypes[[Movement Type]]
Name L_CashTypes: tCashTypes[[Cash Type]]
Name L_Staff: tStaff[[Staff]]
Name L_Customers: tCustomers[[Customer]]
Name L_Suppliers: tSuppliers[[Supplier]]
Name L_Pens: tPens[[Pen ID]]
Name L_Batches: tBatches[[Batch ID]]
Name L_PensGen: OFFSET(HELPER!$A$2,0,0,COUNTA(tPens[[Pen ID]])+1,1)
Name L_PenFilter: OFFSET(HELPER!$B$2,0,0,COUNTA(tPens[[Pen ID]])+1,1)
Name L_BatchFilter: OFFSET(HELPER!$C$2,0,0,COUNTA(tBatches[[Batch ID]])+1,1)
Name L_AnimalFilter: OFFSET(HELPER!$D$2,0,0,COUNTA(tAnimalTypes[[Animal Type]])+1,1)
Name DStart: HELPER!$G$2
Name DEnd: HELPER!$G$3
Name FPen: HELPER!$G$4
Name FBatch: HELPER!$G$5
Name FAnimal: HELPER!$G$6
Name FilterText: HELPER!$G$7
Name TrendStart: TRENDS!$C$4
Name DB_Period: DASHBOARD!$D$5
Name DB_From: DASHBOARD!$D$6
Name DB_To: DASHBOARD!$D$7
Name DB_Pen: DASHBOARD!$D$8
Name DB_Batch: DASHBOARD!$D$9
Name DB_Animal: DASHBOARD!$D$10

Sheet README
B1: FARM ACCOUNTING & INVENTORY MANAGEMENT SYSTEM
B2: Enter transactions once. Everything else is calculated automatically.
B5: WHAT THIS WORKBOOK DOES
B6: Flow | C6: Purchase -> Inventory (store) -> Issue / Usage -> Pen & Batch -> Production -> Sale -> Profitability
B7: Hierarchy | C7: Farm -> Pen (permanent physical house, e.g. P001) -> Batch (one production cycle in a pen, e.g. BROILER-SEP-001) -> Transactions. A pen keeps its ID for life; batches come and go.
B8: Key idea | C8: Purchases are NOT charged to a pen. They go into the store. Cost reaches a pen/batch only when you record an ISSUE (feed) or USAGE (drug). One purchase can therefore be shared by any number of pens.
B9: No daily rows | C9: Record only what happened. If nothing happened in a pen today, enter nothing for it.
B11: COLOURS & CELLS
B12: Green header | C12: Input column - type or pick from the dropdown.
B13: Grey header / grey cell | C13: Automatic formula - do not type. New rows fill these in by themselves.
B14: Yellow cell | C14: A setting or filter you may change (DASHBOARD filters, LISTS settings, TRENDS first month).
B15: Check column | C15: Every log ends with a Check column: OK or a plain-English warning (red). CHECKS sheet counts them.
B16: Protected sheets | C16: DASHBOARD, INVENTORY, BATCH_PROFITABILITY, REPORTS, TRENDS and CHECKS are protected (no password) so formulas are not overwritten. Review > Unprotect Sheet if you must edit.
B18: SHEETS
B19: DASHBOARD | C19: Main page. Farm status, financial & production summary, mortality, charts and pen comparison. Filter by period (Today / This Week / This Month / This Year / All Time / Custom), pen, batch, animal.
B20: PEN_REGISTER | C20: List of pens. You enter ID, name, location, animal type. Current batch, stock and status are automatic.
B21: BATCH_REGISTER | C21: One row per batch/cycle. You enter ID, pen, start date, initial quantity, status (& closing date). Current quantity = initial + transfers in - deaths - animals sold - transfers out.
B22: FEED_PURCHASES | C22: Every feed purchase (bags x bag size = kg; bags x price = cost).
B23: FEED_ISSUES | C23: Feed taken from the store to a pen/batch. Cost per kg is automatic (weighted average).
B24: DRUG_PURCHASES | C24: Every drug/vaccine purchase, with expiry date and lot number. Expiry warnings are automatic.
B25: DRUG_USAGE | C25: Each administration per pen/batch with dosage and quantity. Cost is automatic.
B26: MORTALITY_LOG | C26: Deaths - only on days they happen. Record the observed/recorded cause (use Unknown if unsure).
B27: PRODUCTION_LOG | C27: Weighings (average weight, number sampled) and output such as egg collection.
B28: SALES | C28: Sales linked to pen & batch (or GENERAL for farm-wide items like manure).
B29: OTHER_EXPENSES | C29: Chicks/stock purchase, labour, electricity, repairs ... Pen ID or GENERAL; add Batch ID to charge a batch.
B30: CASHBOOK | C30: Actual money in/out with running balance. Cash is not the same as profit (see below).
... B37: LISTS | C37: Master lists for all dropdowns (feed types + reorder levels, drugs + units, products, categories ...) and settings.
B39: HOW TO ...
B40: Add a new pen | C40: PEN_REGISTER: type the new Pen ID (e.g. P007) in the first empty row under the table, then name, location, animal type. Never reuse or rename an ID that already has records.
B41: Start a new batch | C41: BATCH_REGISTER: new row with a unique Batch ID (e.g. BROILER-OCT-001), Pen ID, animal type, start date, initial quantity, Status = Active. Record the chick cost on OTHER_EXPENSES with the Batch ID.
B42: Close a batch | C42: Set Status = Closed and enter the Closing Date. Do NOT delete anything - the batch's history stays in every report and the pen shows Empty, ready for the next batch.
B43: Record a purchase | C43: FEED_PURCHASES (feed type, bags, bag size, price per bag) or DRUG_PURCHASES (drug, quantity in its stock unit, unit cost, expiry, lot no.). Also enter the payment in CASHBOOK unless bought on Credit.
B44: Issue feed | C44: FEED_ISSUES: date, feed type, pen, batch, kg. Example: 500 kg bought once, then P001 40 kg, P002 60 kg, P003 35 kg, P004 50 kg = four issue rows. If an issue exceeds the store, the Check column warns you.
B45: Record drug usage | C45: DRUG_USAGE: date, drug, pen, batch, reason, dosage text, total quantity used. Same drug in 3 pens = 3 rows.
B46: Record mortality | C46: MORTALITY_LOG: date, pen, batch, number of deaths, cause. Stock updates automatically.
B47: Record a sale | C47: SALES: date, pen, batch, product, quantity, unit price, customer, payment method. Live-animal products reduce batch stock automatically (set per product on LISTS). Add receipt to CASHBOOK.
B48: Record an expense | C48: OTHER_EXPENSES: category, description, Pen ID or GENERAL, Batch ID if it belongs to one batch, amount.
B49: Add a dropdown item | C49: LISTS: type the new item directly under the relevant list - dropdowns grow automatically.
B51: READING THE DASHBOARD
B52: Filters | C52: Choose Period, Pen, Batch and Animal Type in the yellow cells. All cards, the pen comparison, TRENDS and REPORTS follow them.
...

Sheet PEN_REGISTER
A1: PEN REGISTER
A2: Physical pens (permanent). Current batch, stock and status are calculated from BATCH_REGISTER. A pen keeps its ID for life; batches come and go.
A3: ■ GREEN header = you enter / select ■ GREY header = automatic (do not type) Add a new record by typing in the first empty row directly under the table.
A4: Pen ID | B4: Pen Name | C4: Farm/Location | D4: Animal Type | E4: Current Batch ID | F4: Start Date | G4: Initial Stock | H4: Current Stock | I4: Status | J4: Pen Closed | K4: Notes | L4: Check
A5: P001 | B5: Broiler House 1 | C5: Main Farm | D5: Broiler | E5: =IF(COUNTIFS(tBatches[[Pen ID]],tPens[[#This Row],[Pen ID]],tBatches[[Status]],"Active")=0,"",IF(COUNTIFS(tBatches[[Pen ID]],tPens[[#This Row],[Pen ID]],tBatches[[Status]],"Active")=1,INDEX(tBatches[[Batch ID]],MATCH(tPens[[#This Row],[Pen ID]],tBatches[[Active Pen Key]],0)),INDEX(tBatches[[Batch ID]],MATCH(tPens[[#This Row],[Pen ID]],tBatches[[Active Pen Key]],0))&" +"&(COUNTIFS(tBatches[[Pen ID]],tPens[[#This Row],[Pen ID]],tBatches[[Status]],"Active")-1)&" more")) | F5: =IF(COUNTIFS(tBatches[[Pen ID]],tPens[[#This Row],[Pen ID]],tBatches[[Status]],"Active")=0,"",_xlfn.MINIFS(tBatches[[Batch Start Date]],tBatches[[Pen ID]],tPens[[#This Row],[Pen ID]],tBatches[[Status]],"Active")) | G5: =SUMIFS(tBatches[[Initial Quantity]],tBatches[[Pen ID]],tPens[[#This Row],[Pen ID]],tBatches[[Status]],"Active") | H5: =SUMIFS(tBatches[[Current Quantity]],tBatches[[Pen ID]],tPens[[#This Row],[Pen ID]],tBatches[[Status]],"Active") | I5: =IF(tPens[[#This Row],[Pen ID]]="","",IF(tPens[[#This Row],[Pen Closed]]="Yes","Closed",IF(COUNTIFS(tBatches[[Pen ID]],tPens[[#This Row],[Pen ID]],tBatches[[Status]],"Active")>0,"Active","Empty"))) | J5: No | K5: SAMPLE DATA - delete or replace | L5: =IF(AND(tPens[[#This Row],[Pen ID]]=""),"",IF(COUNTIF(tPens[[Pen ID]],tPens[[#This Row],[Pen ID]])>1,"Duplicate Pen ID",IF(tPens[[#This Row],[Pen ID]]="GENERAL","GENERAL is reserved - use another ID",IF(AND(tPens[[#This Row],[Pen Closed]]="Yes",COUNTIFS(tBatches[[Pen ID]],tPens[[#This Row],[Pen ID]],tBatches[[Status]],"Active")>0),"Pen marked closed but has an active batch","OK"))))
A6: P002 | B6: Broiler House 2 | C6: Main Farm | D6: Broiler | E6: =IF(COUNTIFS(tBatches[[Pen ID]],tPens[[#This Row],[Pen ID]],tBatches[[Status]],"Active")=0,"",IF(COUNTIFS(tBatches[[Pen ID]],tPens[[#This Row],[Pen ID]],tBatches[[Status]],"Active")=1,INDEX(tBatches[[Batch ID]],MATCH(tPens[[#This Row],[Pen ID]],tBatches[[Active Pen Key]],0)),INDEX(tBatches[[Batch ID]],MATCH(tPens[[#This Row],[Pen ID]],tBatches[[Active Pen Key]],0))&" +"&(COUNTIFS(tBatches[[Pen ID]],tPens[[#This Row],[Pen ID]],tBatches[[Status]],"Active")-1)&" more")) | F6: =IF(COUNTIFS(tBatches[[Pen ID]],tPens[[#This Row],[Pen ID]],tBatches[[Status]],"Active")=0,"",_xlfn.MINIFS(tBatches[[Batch Start Date]],tBatches[[Pen ID]],tPens[[#This Row],[Pen ID]],tBatches[[Status]],"Active")) | G6: =SUMIFS(tBatches[[Initial Quantity]],tBatches[[Pen ID]],tPens[[#This Row],[Pen ID]],tBatches[[Status]],"Active") | H6: =SUMIFS(tBatches[[Current Quantity]],tBatches[[Pen ID]],tPens[[#This Row],[Pen ID]],tBatches[[Status]],"Active") | I6: =IF(tPens[[#This Row],[Pen ID]]="","",IF(tPens[[#This Row],[Pen Closed]]="Yes","Closed",IF(COUNTIFS(tBatches[[Pen ID]],tPens[[#This Row],[Pen ID]],tBatches[[Status]],"Active")>0,"Active","Empty"))) | J6: No | K6: SAMPLE DATA - delete or replace | L6: =IF(AND(tPens[[#This Row],[Pen ID]]=""),"",IF(COUNTIF(tPens[[Pen ID]],tPens[[#This Row],[Pen ID]])>1,"Duplicate Pen ID",IF(tPens[[#This Row],[Pen ID]]="GENERAL","GENERAL is reserved - use another ID",IF(AND(tPens[[#This Row],[Pen Closed]]="Yes",COUNTIFS(tBatches[[Pen ID]],tPens[[#This Row],[Pen ID]],tBatches[[Status]],"Active")>0),"Pen marked closed but has an active batch","OK"))))
A7: P003 | B7: Broiler House 3 | C7: Main Farm | D7: Broiler | E7: =IF(COUNTIFS(tBatches[[Pen ID]],tPens[[#This Row],[Pen ID]],tBatches[[Status]],"Active")=0,"",IF(COUNTIFS(tBatches[[Pen ID]],tPens[[#This Row],[Pen ID]],tBatches[[Status]],"Active")=1,INDEX(tBatches[[Batch ID]],MATCH(tPens[[#This Row],[Pen ID]],tBatches[[Active Pen Key]],0)),INDEX(tBatches[[Batch ID]],MATCH(tPens[[#This Row],[Pen ID]],tBatches[[Active Pen Key]],0))&" +"&(COUNTIFS(tBatches[[Pen ID]],tPens[[#This Row],[Pen ID]],tBatches[[Status]],"Active")-1)&" more")) | F7: =IF(COUNTIFS(tBatches[[Pen ID]],tPens[[#This Row],[Pen ID]],tBatches[[Status]],"Active")=0,"",_xlfn.MINIFS(tBatches[[Batch Start Date]],tBatches[[Pen ID]],tPens[[#This Row],[Pen ID]],tBatches[[Status]],"Active")) | G7: =SUMIFS(tBatches[[Initial Quantity]],tBatches[[Pen ID]],tPens[[#This Row],[Pen ID]],tBatches[[Status]],"Active") | H7: =SUMIFS(tBatches[[Current Quantity]],tBatches[[Pen ID]],tPens[[#This Row],[Pen ID]],tBatches[[Status]],"Active") | I7: =IF(tPens[[#This Row],[Pen ID]]="","",IF(tPens[[#This Row],[Pen Closed]]="Yes","Closed",IF(COUNTIFS(tBatches[[Pen ID]],tPens[[#This Row],[Pen ID]],tBatches[[Status]],"Active")>0,"Active","Empty"))) | J7: No | K7: SAMPLE DATA - delete or replace | L7: =IF(AND(tPens[[#This Row],[Pen ID]]=""),"",IF(COUNTIF(tPens[[Pen ID]],tPens[[#This Row],[Pen ID]])>1,"Duplicate Pen ID",IF(tPens[[#This Row],[Pen ID]]="GENERAL","GENERAL is reserved - use another ID",IF(AND(tPens[[#This Row],[Pen Closed]]="Yes",COUNTIFS(tBatches[[Pen ID]],tPens[[#This Row],[Pen ID]],tBatches[[Status]],"Active")>0),"Pen marked closed but has an active batch","OK"))))
A8: P004 | B8: Broiler House 4 | C8: Main Farm | D8: Broiler | E8: =IF(COUNTIFS(tBatches[[Pen ID]],tPens[[#This Row],[Pen ID]],tBatches[[Status]],"Active")=0,"",IF(COUNTIFS(tBatches[[Pen ID]],tPens[[#This Row],[Pen ID]],tBatches[[Status]],"Active")=1,INDEX(tBatches[[Batch ID]],MATCH(tPens[[#This Row],[Pen ID]],tBatches[[Active Pen Key]],0)),INDEX(tBatches[[Batch ID]],MATCH(tPens[[#This Row],[Pen ID]],tBatches[[Active Pen Key]],0))&" +"&(COUNTIFS(tBatches[[Pen ID]],tPens[[#This Row],[Pen ID]],tBatches[[Status]],"Active")-1)&" more")) | F8: =IF(COUNTIFS(tBatches[[Pen ID]],tPens[[#This Row],[Pen ID]],tBatches[[Status]],"Active")=0,"",_xlfn.MINIFS(tBatches[[Batch Start Date]],tBatches[[Pen ID]],tPens[[#This Row],[Pen ID]],tBatches[[Status]],"Active")) | G8: =SUMIFS(tBatches[[Initial Quantity]],tBatches[[Pen ID]],tPens[[#This Row],[Pen ID]],tBatches[[Status]],"Active") | H8: =SUMIFS(tBatches[[Current Quantity]],tBatches[[Pen ID]],tPens[[#This Row],[Pen ID]],tBatches[[Status]],"Active") | I8: =IF(tPens[[#This Row],[Pen ID]]="","",IF(tPens[[#This Row],[Pen Closed]]="Yes","Closed",IF(COUNTIFS(tBatches[[Pen ID]],tPens[[#This Row],[Pen ID]],tBatches[[Status]],"Active")>0,"Active","Empty"))) | J8: No | K8: SAMPLE DATA - delete or replace | L8: =IF(AND(tPens[[#This Row],[Pen ID]]=""),"",IF(COUNTIF(tPens[[Pen ID]],tPens[[#This Row],[Pen ID]])>1,"Duplicate Pen ID",IF(tPens[[#This Row],[Pen ID]]="GENERAL","GENERAL is reserved - use another ID",IF(AND(tPens[[#This Row],[Pen Closed]]="Yes",COUNTIFS(tBatches[[Pen ID]],tPens[[#This Row],[Pen ID]],tBatches[[Status]],"Active")>0),"Pen marked closed but has an active batch","OK"))))
A9: P005 | B9: Layer House 1 | C9: Main Farm | D9: Layer | E9: =IF(COUNTIFS(tBatches[[Pen ID]],tPens[[#This Row],[Pen ID]],tBatches[[Status]],"Active")=0,"",IF(COUNTIFS(tBatches[[Pen ID]],tPens[[#This Row],[Pen ID]],tBatches[[Status]],"Active")=1,INDEX(tBatches[[Batch ID]],MATCH(tPens[[#This Row],[Pen ID]],tBatches[[Active Pen Key]],0)),INDEX(tBatches[[Batch ID]],MATCH(tPens[[#This Row],[Pen ID]],tBatches[[Active Pen Key]],0))&" +"&(COUNTIFS(tBatches[[Pen ID]],tPens[[#This Row],[Pen ID]],tBatches[[Status]],"Active")-1)&" more")) | F9: =IF(COUNTIFS(tBatches[[Pen ID]],tPens[[#This Row],[Pen ID]],tBatches[[Status]],"Active")=0,"",_xlfn.MINIFS(tBatches[[Batch Start Date]],tBatches[[Pen ID]],tPens[[#This Row],[Pen ID]],tBatches[[Status]],"Active")) | G9: =SUMIFS(tBatches[[Initial Quantity]],tBatches[[Pen ID]],tPens[[#This Row],[Pen ID]],tBatches[[Status]],"Active") | H9: =SUMIFS(tBatches[[Current Quantity]],tBatches[[Pen ID]],tPens[[#This Row],[Pen ID]],tBatches[[Status]],"Active") | I9: =IF(tPens[[#This Row],[Pen ID]]="","",IF(tPens[[#This Row],[Pen Closed]]="Yes","Closed",IF(COUNTIFS(tBatches[[Pen ID]],tPens[[#This Row],[Pen ID]],tBatches[[Status]],"Active")>0,"Active","Empty"))) | J9: No | K9: SAMPLE DATA - delete or replace | L9: =IF(AND(tPens[[#This Row],[Pen ID]]=""),"",IF(COUNTIF(tPens[[Pen ID]],tPens[[#This Row],[Pen ID]])>1,"Duplicate Pen ID",IF(tPens[[#This Row],[Pen ID]]="GENERAL","GENERAL is reserved - use another ID",IF(AND(tPens[[#This Row],[Pen Closed]]="Yes",COUNTIFS(tBatches[[Pen ID]],tPens[[#This Row],[Pen ID]],tBatches[[Status]],"Active")>0),"Pen marked closed but has an active batch","OK"))))
A10: P006 | B10: Broiler House 5 | C10: Annex | D10: Broiler | E10: =IF(COUNTIFS(tBatches[[Pen ID]],tPens[[#This Row],[Pen ID]],tBatches[[Status]],"Active")=0,"",IF(COUNTIFS(tBatches[[Pen ID]],tPens[[#This Row],[Pen ID]],tBatches[[Status]],"Active")=1,INDEX(tBatches[[Batch ID]],MATCH(tPens[[#This Row],[Pen ID]],tBatches[[Active Pen Key]],0)),INDEX(tBatches[[Batch ID]],MATCH(tPens[[#This Row],[Pen ID]],tBatches[[Active Pen Key]],0))&" +"&(COUNTIFS(tBatches[[Pen ID]],tPens[[#This Row],[Pen ID]],tBatches[[Status]],"Active")-1)&" more")) | F10: =IF(COUNTIFS(tBatches[[Pen ID]],tPens[[#This Row],[Pen ID]],tBatches[[Status]],"Active")=0,"",_xlfn.MINIFS(tBatches[[Batch Start Date]],tBatches[[Pen ID]],tPens[[#This Row],[Pen ID]],tBatches[[Status]],"Active")) | G10: =SUMIFS(tBatches[[Initial Quantity]],tBatches[[Pen ID]],tPens[[#This Row],[Pen ID]],tBatches[[Status]],"Active") | H10: =SUMIFS(tBatches[[Current Quantity]],tBatches[[Pen ID]],tPens[[#This Row],[Pen ID]],tBatches[[Status]],"Active") | I10: =IF(tPens[[#This Row],[Pen ID]]="","",IF(tPens[[#This Row],[Pen Closed]]="Yes","Closed",IF(COUNTIFS(tBatches[[Pen ID]],tPens[[#This Row],[Pen ID]],tBatches[[Status]],"Active")>0,"Active","Empty"))) | J10: No | K10: SAMPLE DATA - delete or replace | L10: =IF(AND(tPens[[#This Row],[Pen ID]]=""),"",IF(COUNTIF(tPens[[Pen ID]],tPens[[#This Row],[Pen ID]])>1,"Duplicate Pen ID",IF(tPens[[#This Row],[Pen ID]]="GENERAL","GENERAL is reserved - use another ID",IF(AND(tPens[[#This Row],[Pen Closed]]="Yes",COUNTIFS(tBatches[[Pen ID]],tPens[[#This Row],[Pen ID]],tBatches[[Status]],"Active")>0),"Pen marked closed but has an active batch","OK"))))

Sheet BATCH_REGISTER
A1: BATCH REGISTER
A2: One row per production cycle. A batch lives in one pen. When finished set Status = Closed and enter the Closing Date - its history is kept for ever and the pen becomes free for a new batch.
A3: ■ GREEN header = you enter / select ■ GREY header = automatic (do not type) Add a new record by typing in the first empty row directly under the table.
A4: Batch ID | B4: Pen ID | C4: Animal Type | D4: Batch Start Date | E4: Initial Quantity | F4: Source/Supplier | G4: Breed/Type | H4: Current Quantity | I4: Closing Date | J4: Status | K4: Notes | L4: Transfers In / Added | M4: Deaths | N4: Heads Sold | O4: Transfers Out | P4: Total Placed | Q4: Age (days) | R4: Active Pen Key | S4: Check
A5: BROILER-SEP-001 | B5: P001 | C5: Broiler | D5: 46266 | E5: 500 | F5: Hatchery (sample) | G5: Cobb 500 | H5: =tBatches[[#This Row],[Total Placed]]-tBatches[[#This Row],[Deaths]]-tBatches[[#This Row],[Heads Sold]]-tBatches[[#This Row],[Transfers Out]] | J5: Active | K5: SAMPLE DATA - delete or replace | L5: =SUMIFS(tMoves[[Quantity In]],tMoves[[Batch ID]],tBatches[[#This Row],[Batch ID]]) | M5: =SUMIFS(tMort[[Number of Deaths]],tMort[[Batch ID]],tBatches[[#This Row],[Batch ID]]) | N5: =SUMIFS(tSales[[Heads Removed]],tSales[[Batch ID]],tBatches[[#This Row],[Batch ID]]) | O5: =SUMIFS(tMoves[[Quantity Out]],tMoves[[Batch ID]],tBatches[[#This Row],[Batch ID]]) | P5: =N(tBatches[[#This Row],[Initial Quantity]])+tBatches[[#This Row],[Transfers In / Added]] | Q5: =IF(NOT(ISNUMBER(tBatches[[#This Row],[Batch Start Date]])),"",IF(N(tBatches[[#This Row],[Closing Date]])>0,tBatches[[#This Row],[Closing Date]],TODAY())-tBatches[[#This Row],[Batch Start Date]]+1) | R5: =IF(tBatches[[#This Row],[Status]]="Active",tBatches[[#This Row],[Pen ID]],"") | S5: =IF(AND(tBatches[[#This Row],[Batch ID]]="",tBatches[[#This Row],[Pen ID]]=""),"",IF(tBatches[[#This Row],[Batch ID]]="","Missing Batch ID",IF(COUNTIF(tBatches[[Batch ID]],tBatches[[#This Row],[Batch ID]])>1,"Duplicate Batch ID",IF(COUNTIF(tPens[[Pen ID]],tBatches[[#This Row],[Pen ID]])=0,"Pen is not in PEN_REGISTER",IF(NOT(ISNUMBER(tBatches[[#This Row],[Batch Start Date]])),"Missing start date",IF(N(tBatches[[#This Row],[Initial Quantity]])<=0,"Initial quantity must be > 0",IF(tBatches[[#This Row],[Status]]="","Missing status",IF(tBatches[[#This Row],[Current Quantity]]<0,"Negative stock - more deaths/sales than animals",IF(AND(tBatches[[#This Row],[Status]]="Closed",N(tBatches[[#This Row],[Closing Date]])=0),"Closed batch needs a closing date",IF(AND(tBatches[[#This Row],[Status]]="Closed",tBatches[[#This Row],[Current Quantity]]>0),"Closed with "&tBatches[[#This Row],[Current Quantity]]&" animals unaccounted for",IF(AND(N(tBatches[[#This Row],[Closing Date]])>0,N(tBatches[[#This Row],[Closing Date]])<tBatches[[#This Row],[Batch Start Date]]),"Closing date is before start date","OK")))))))))))
A6: BROILER-SEP-002 | B6: P002 | C6: Broiler | D6: 46266 | E6: 600 | F6: Hatchery (sample) | G6: Ross 308 | H6: =tBatches[[#This Row],[Total Placed]]-tBatches[[#This Row],[Deaths]]-tBatches[[#This Row],[Heads Sold]]-tBatches[[#This Row],[Transfers Out]] | J6: Active | K6: SAMPLE DATA - delete or replace | L6: =SUMIFS(tMoves[[Quantity In]],tMoves[[Batch ID]],tBatches[[#This Row],[Batch ID]]) | M6: =SUMIFS(tMort[[Number of Deaths]],tMort[[Batch ID]],tBatches[[#This Row],[Batch ID]]) | N6: =SUMIFS(tSales[[Heads Removed]],tSales[[Batch ID]],tBatches[[#This Row],[Batch ID]]) | O6: =SUMIFS(tMoves[[Quantity Out]],tMoves[[Batch ID]],tBatches[[#This Row],[Batch ID]]) | P6: =N(tBatches[[#This Row],[Initial Quantity]])+tBatches[[#This Row],[Transfers In / Added]] | Q6: =IF(NOT(ISNUMBER(tBatches[[#This Row],[Batch Start Date]])),"",IF(N(tBatches[[#This Row],[Closing Date]])>0,tBatches[[#This Row],[Closing Date]],TODAY())-tBatches[[#This Row],[Batch Start Date]]+1) | R6: =IF(tBatches[[#This Row],[Status]]="Active",tBatches[[#This Row],[Pen ID]],"") | S6: =IF(AND(tBatches[[#This Row],[Batch ID]]="",tBatches[[#This Row],[Pen ID]]=""),"",IF(tBatches[[#This Row],[Batch ID]]="","Missing Batch ID",IF(COUNTIF(tBatches[[Batch ID]],tBatches[[#This Row],[Batch ID]])>1,"Duplicate Batch ID",IF(COUNTIF(tPens[[Pen ID]],tBatches[[#This Row],[Pen ID]])=0,"Pen is not in PEN_REGISTER",IF(NOT(ISNUMBER(tBatches[[#This Row],[Batch Start Date]])),"Missing start date",IF(N(tBatches[[#This Row],[Initial Quantity]])<=0,"Initial quantity must be > 0",IF(tBatches[[#This Row],[Status]]="","Missing status",IF(tBatches[[#This Row],[Current Quantity]]<0,"Negative stock - more deaths/sales than animals",IF(AND(tBatches[[#This Row],[Status]]="Closed",N(tBatches[[#This Row],[Closing Date]])=0),"Closed batch needs a closing date",IF(AND(tBatches[[#This Row],[Status]]="Closed",tBatches[[#This Row],[Current Quantity]]>0),"Closed with "&tBatches[[#This Row],[Current Quantity]]&" animals unaccounted for",IF(AND(N(tBatches[[#This Row],[Closing Date]])>0,N(tBatches[[#This Row],[Closing Date]])<tBatches[[#This Row],[Batch Start Date]]),"Closing date is before start date","OK")))))))))))
A7: BROILER-SEP-003 | B7: P003 | C7: Broiler | D7: 46267 | E7: 450 | F7: Hatchery (sample) | G7: Cobb 500 | H7: =tBatches[[#This Row],[Total Placed]]-tBatches[[#This Row],[Deaths]]-tBatches[[#This Row],[Heads Sold]]-tBatches[[#This Row],[Transfers Out]] | J7: Active | K7: SAMPLE DATA - delete or replace | L7: =SUMIFS(tMoves[[Quantity In]],tMoves[[Batch ID]],tBatches[[#This Row],[Batch ID]]) | M7: =SUMIFS(tMort[[Number of Deaths]],tMort[[Batch ID]],tBatches[[#This Row],[Batch ID]]) | N7: =SUMIFS(tSales[[Heads Removed]],tSales[[Batch ID]],tBatches[[#This Row],[Batch ID]]) | O7: =SUMIFS(tMoves[[Quantity Out]],tMoves[[Batch ID]],tBatches[[#This Row],[Batch ID]]) | P7: =N(tBatches[[#This Row],[Initial Quantity]])+tBatches[[#This Row],[Transfers In / Added]] | Q7: =IF(NOT(ISNUMBER(tBatches[[#This Row],[Batch Start Date]])),"",IF(N(tBatches[[#This Row],[Closing Date]])>0,tBatches[[#This Row],[Closing Date]],TODAY())-tBatches[[#This Row],[Batch Start Date]]+1) | R7: =IF(tBatches[[#This Row],[Status]]="Active",tBatches[[#This Row],[Pen ID]],"") | S7: =IF(AND(tBatches[[#This Row],[Batch ID]]="",tBatches[[#This Row],[Pen ID]]=""),"",IF(tBatches[[#This Row],[Batch ID]]="","Missing Batch ID",IF(COUNTIF(tBatches[[Batch ID]],tBatches[[#This Row],[Batch ID]])>1,"Duplicate Batch ID",IF(COUNTIF(tPens[[Pen ID]],tBatches[[#This Row],[Pen ID]])=0,"Pen is not in PEN_REGISTER",IF(NOT(ISNUMBER(tBatches[[#This Row],[Batch Start Date]])),"Missing start date",IF(N(tBatches[[#This Row],[Initial Quantity]])<=0,"Initial quantity must be > 0",IF(tBatches[[#This Row],[Status]]="","Missing status",IF(tBatches[[#This Row],[Current Quantity]]<0,"Negative stock - more deaths/sales than animals",IF(AND(tBatches[[#This Row],[Status]]="Closed",N(tBatches[[#This Row],[Closing Date]])=0),"Closed batch needs a closing date",IF(AND(tBatches[[#This Row],[Status]]="Closed",tBatches[[#This Row],[Current Quantity]]>0),"Closed with "&tBatches[[#This Row],[Current Quantity]]&" animals unaccounted for",IF(AND(N(tBatches[[#This Row],[Closing Date]])>0,N(tBatches[[#This Row],[Closing Date]])<tBatches[[#This Row],[Batch Start Date]]),"Closing date is before start date","OK")))))))))))
A8: BROILER-SEP-004 | B8: P004 | C8: Broiler | D8: 46267 | E8: 550 | F8: Hatchery (sample) | G8: Arbor Acres | H8: =tBatches[[#This Row],[Total Placed]]-tBatches[[#This Row],[Deaths]]-tBatches[[#This Row],[Heads Sold]]-tBatches[[#This Row],[Transfers Out]] | J8: Active | K8: SAMPLE DATA - delete or replace | L8: =SUMIFS(tMoves[[Quantity In]],tMoves[[Batch ID]],tBatches[[#This Row],[Batch ID]]) | M8: =SUMIFS(tMort[[Number of Deaths]],tMort[[Batch ID]],tBatches[[#This Row],[Batch ID]]) | N8: =SUMIFS(tSales[[Heads Removed]],tSales[[Batch ID]],tBatches[[#This Row],[Batch ID]]) | O8: =SUMIFS(tMoves[[Quantity Out]],tMoves[[Batch ID]],tBatches[[#This Row],[Batch ID]]) | P8: =N(tBatches[[#This Row],[Initial Quantity]])+tBatches[[#This Row],[Transfers In / Added]] | Q8: =IF(NOT(ISNUMBER(tBatches[[#This Row],[Batch Start Date]])),"",IF(N(tBatches[[#This Row],[Closing Date]])>0,tBatches[[#This Row],[Closing Date]],TODAY())-tBatches[[#This Row],[Batch Start Date]]+1) | R8: =IF(tBatches[[#This Row],[Status]]="Active",tBatches[[#This Row],[Pen ID]],"") | S8: =IF(AND(tBatches[[#This Row],[Batch ID]]="",tBatches[[#This Row],[Pen ID]]=""),"",IF(tBatches[[#This Row],[Batch ID]]="","Missing Batch ID",IF(COUNTIF(tBatches[[Batch ID]],tBatches[[#This Row],[Batch ID]])>1,"Duplicate Batch ID",IF(COUNTIF(tPens[[Pen ID]],tBatches[[#This Row],[Pen ID]])=0,"Pen is not in PEN_REGISTER",IF(NOT(ISNUMBER(tBatches[[#This Row],[Batch Start Date]])),"Missing start date",IF(N(tBatches[[#This Row],[Initial Quantity]])<=0,"Initial quantity must be > 0",IF(tBatches[[#This Row],[Status]]="","Missing status",IF(tBatches[[#This Row],[Current Quantity]]<0,"Negative stock - more deaths/sales than animals",IF(AND(tBatches[[#This Row],[Status]]="Closed",N(tBatches[[#This Row],[Closing Date]])=0),"Closed batch needs a closing date",IF(AND(tBatches[[#This Row],[Status]]="Closed",tBatches[[#This Row],[Current Quantity]]>0),"Closed with "&tBatches[[#This Row],[Current Quantity]]&" animals unaccounted for",IF(AND(N(tBatches[[#This Row],[Closing Date]])>0,N(tBatches[[#This Row],[Closing Date]])<tBatches[[#This Row],[Batch Start Date]]),"Closing date is before start date","OK")))))))))))
A9: LAYER-JUN-001 | B9: P005 | C9: Layer | D9: 46174 | E9: 400 | F9: Hatchery (sample) | G9: Isa Brown (point-of-lay) | H9: =tBatches[[#This Row],[Total Placed]]-tBatches[[#This Row],[Deaths]]-tBatches[[#This Row],[Heads Sold]]-tBatches[[#This Row],[Transfers Out]] | J9: Active | K9: SAMPLE DATA - delete or replace | L9: =SUMIFS(tMoves[[Quantity In]],tMoves[[Batch ID]],tBatches[[#This Row],[Batch ID]]) | M9: =SUMIFS(tMort[[Number of Deaths]],tMort[[Batch ID]],tBatches[[#This Row],[Batch ID]]) | N9: =SUMIFS(tSales[[Heads Removed]],tSales[[Batch ID]],tBatches[[#This Row],[Batch ID]]) | O9: =SUMIFS(tMoves[[Quantity Out]],tMoves[[Batch ID]],tBatches[[#This Row],[Batch ID]]) | P9: =N(tBatches[[#This Row],[Initial Quantity]])+tBatches[[#This Row],[Transfers In / Added]] | Q9: =IF(NOT(ISNUMBER(tBatches[[#This Row],[Batch Start Date]])),"",IF(N(tBatches[[#This Row],[Closing Date]])>0,tBatches[[#This Row],[Closing Date]],TODAY())-tBatches[[#This Row],[Batch Start Date]]+1) | R9: =IF(tBatches[[#This Row],[Status]]="Active",tBatches[[#This Row],[Pen ID]],"") | S9: =IF(AND(tBatches[[#This Row],[Batch ID]]="",tBatches[[#This Row],[Pen ID]]=""),"",IF(tBatches[[#This Row],[Batch ID]]="","Missing Batch ID",IF(COUNTIF(tBatches[[Batch ID]],tBatches[[#This Row],[Batch ID]])>1,"Duplicate Batch ID",IF(COUNTIF(tPens[[Pen ID]],tBatches[[#This Row],[Pen ID]])=0,"Pen is not in PEN_REGISTER",IF(NOT(ISNUMBER(tBatches[[#This Row],[Batch Start Date]])),"Missing start date",IF(N(tBatches[[#This Row],[Initial Quantity]])<=0,"Initial quantity must be > 0",IF(tBatches[[#This Row],[Status]]="","Missing status",IF(tBatches[[#This Row],[Current Quantity]]<0,"Negative stock - more deaths/sales than animals",IF(AND(tBatches[[#This Row],[Status]]="Closed",N(tBatches[[#This Row],[Closing Date]])=0),"Closed batch needs a closing date",IF(AND(tBatches[[#This Row],[Status]]="Closed",tBatches[[#This Row],[Current Quantity]]>0),"Closed with "&tBatches[[#This Row],[Current Quantity]]&" animals unaccounted for",IF(AND(N(tBatches[[#This Row],[Closing Date]])>0,N(tBatches[[#This Row],[Closing Date]])<tBatches[[#This Row],[Batch Start Date]]),"Closing date is before start date","OK")))))))))))
A10: BROILER-JUL-001 | B10: P006 | C10: Broiler | D10: 46204 | E10: 300 | F10: Hatchery (sample) | G10: Cobb 500 | H10: =tBatches[[#This Row],[Total Placed]]-tBatches[[#This Row],[Deaths]]-tBatches[[#This Row],[Heads Sold]]-tBatches[[#This Row],[Transfers Out]] | I10: 46252 | J10: Closed | K10: SAMPLE DATA - delete or replace. Closed batch: history kept, pen P006 now Empty and can take a new batch. | L10: =SUMIFS(tMoves[[Quantity In]],tMoves[[Batch ID]],tBatches[[#This Row],[Batch ID]]) | M10: =SUMIFS(tMort[[Number of Deaths]],tMort[[Batch ID]],tBatches[[#This Row],[Batch ID]]) | N10: =SUMIFS(tSales[[Heads Removed]],tSales[[Batch ID]],tBatches[[#This Row],[Batch ID]]) | O10: =SUMIFS(tMoves[[Quantity Out]],tMoves[[Batch ID]],tBatches[[#This Row],[Batch ID]]) | P10: =N(tBatches[[#This Row],[Initial Quantity]])+tBatches[[#This Row],[Transfers In / Added]] | Q10: =IF(NOT(ISNUMBER(tBatches[[#This Row],[Batch Start Date]])),"",IF(N(tBatches[[#This Row],[Closing Date]])>0,tBatches[[#This Row],[Closing Date]],TODAY())-tBatches[[#This Row],[Batch Start Date]]+1) | R10: =IF(tBatches[[#This Row],[Status]]="Active",tBatches[[#This Row],[Pen ID]],"") | S10: =IF(AND(tBatches[[#This Row],[Batch ID]]="",tBatches[[#This Row],[Pen ID]]=""),"",IF(tBatches[[#This Row],[Batch ID]]="","Missing Batch ID",IF(COUNTIF(tBatches[[Batch ID]],tBatches[[#This Row],[Batch ID]])>1,"Duplicate Batch ID",IF(COUNTIF(tPens[[Pen ID]],tBatches[[#This Row],[Pen ID]])=0,"Pen is not in PEN_REGISTER",IF(NOT(ISNUMBER(tBatches[[#This Row],[Batch Start Date]])),"Missing start date",IF(N(tBatches[[#This Row],[Initial Quantity]])<=0,"Initial quantity must be > 0",IF(tBatches[[#This Row],[Status]]="","Missing status",IF(tBatches[[#This Row],[Current Quantity]]<0,"Negative stock - more deaths/sales than animals",IF(AND(tBatches[[#This Row],[Status]]="Closed",N(tBatches[[#This Row],[Closing Date]])=0),"Closed batch needs a closing date",IF(AND(tBatches[[#This Row],[Status]]="Closed",tBatches[[#This Row],[Current Quantity]]>0),"Closed with "&tBatches[[#This Row],[Current Quantity]]&" animals unaccounted for",IF(AND(N(tBatches[[#This Row],[Closing Date]])>0,N(tBatches[[#This Row],[Closing Date]])<tBatches[[#This Row],[Batch Start Date]]),"Closing date is before start date","OK")))))))))))

Sheet FEED_PURCHASES
A1: FEED PURCHASES
A2: Record each purchase ONCE. Feed goes into the store (INVENTORY) - it only becomes a pen/batch cost when it is issued on FEED_ISSUES. Inventory unit = kg.
A3: ■ GREEN header = you enter / select ■ GREY header = automatic (do not type) Add a new record by typing in the first empty row directly under the table.
A4: Date | B4: Purchase ID | C4: Feed Type | D4: Supplier | E4: Quantity in Bags | F4: Bag Size in kg | G4: Total Quantity in kg | H4: Price per Bag | I4: Total Cost | J4: Cost per kg | K4: Payment Method | L4: Reference | M4: Notes | N4: Purchase No. of Type | O4: Stock Before Purchase kg | P4: Avg Cost per kg After Purchase | Q4: Check
A5: 46204 | B5: ="FP-"&TEXT(ROW()-ROW(tFeedPur[[#Headers],[Date]]),"00000") | C5: Starter | D5: Feed Supplier A (sample) | E5: 12 | F5: 25 | G5: =N(tFeedPur[[#This Row],[Quantity in Bags]])*N(tFeedPur[[#This Row],[Bag Size in kg]]) | H5: 14000 | I5: =N(tFeedPur[[#This Row],[Quantity in Bags]])*N(tFeedPur[[#This Row],[Price per Bag]]) | J5: =IFERROR(tFeedPur[[#This Row],[Total Cost]]/tFeedPur[[#This Row],[Total Quantity in kg]],0) | K5: Transfer | L5: INV-1001 | M5: SAMPLE DATA - delete or replace | N5: =COUNTIF(INDEX(tFeedPur[[Feed Type]],1):tFeedPur[[#This Row],[Feed Type]],tFeedPur[[#This Row],[Feed Type]]) | O5: =MAX(0,IF((ROW()-ROW(tFeedPur[[#Headers],[Date]]))=1,0,SUMIFS(INDEX(tFeedPur[[Total Quantity in kg]],1):INDEX(tFeedPur[[Total Quantity in kg]],(ROW()-ROW(tFeedPur[[#Headers],[Date]]))-1),INDEX(tFeedPur[[Feed Type]],1):INDEX(tFeedPur[[Feed Type]],(ROW()-ROW(tFeedPur[[#Headers],[Date]]))-1),tFeedPur[[#This Row],[Feed Type]]))-SUMIFS(tFeedIss[[Quantity Issued in kg]],tFeedIss[[Feed Type]],tFeedPur[[#This Row],[Feed Type]],tFeedIss[[Date]],"<"&tFeedPur[[#This Row],[Date]])) | P5: =IFERROR((tFeedPur[[#This Row],[Stock Before Purchase kg]]*IF(tFeedPur[[#This Row],[Purchase No. of Type]]=1,0,LOOKUP(2,1/(INDEX(tFeedPur[[Feed Type]],1):INDEX(tFeedPur[[Feed Type]],(ROW()-ROW(tFeedPur[[#Headers],[Date]]))-1)=tFeedPur[[#This Row],[Feed Type]]),INDEX(tFeedPur[[Avg Cost per kg After Purchase]],1):INDEX(tFeedPur[[Avg Cost per kg After Purchase]],(ROW()-ROW(tFeedPur[[#Headers],[Date]]))-1)))+N(tFeedPur[[#This Row],[Total Cost]]))/(tFeedPur[[#This Row],[Stock Before Purchase kg]]+N(tFeedPur[[#This Row],[Total Quantity in kg]])),IF(tFeedPur[[#This Row],[Purchase No. of Type]]=1,0,LOOKUP(2,1/(INDEX(tFeedPur[[Feed Type]],1):INDEX(tFeedPur[[Feed Type]],(ROW()-ROW(tFeedPur[[#Headers],[Date]]))-1)=tFeedPur[[#This Row],[Feed Type]]),INDEX(tFeedPur[[Avg Cost per kg After Purchase]],1):INDEX(tFeedPur[[Avg Cost per kg After Purchase]],(ROW()-ROW(tFeedPur[[#Headers],[Date]]))-1)))) | Q5: =IF(AND(tFeedPur[[#This Row],[Date]]="",tFeedPur[[#This Row],[Feed Type]]="",tFeedPur[[#This Row],[Quantity in Bags]]=""),"",IF(tFeedPur[[#This Row],[Date]]="","Missing date",IF(NOT(ISNUMBER(tFeedPur[[#This Row],[Date]])),"Date is not a valid date",IF(AND((ROW()-ROW(tFeedPur[[#Headers],[Date]]))>1,tFeedPur[[#This Row],[Date]]<INDEX(tFeedPur[[Date]],MAX(1,(ROW()-ROW(tFeedPur[[#Headers],[Date]]))-1))),"Out of date order - insert this row after earlier purchases",IF(tFeedPur[[#This Row],[Feed Type]]="","Missing feed type",IF(COUNTIF(tFeedTypes[[Feed Type]],tFeedPur[[#This Row],[Feed Type]])=0,"Feed type not in LISTS",IF(N(tFeedPur[[#This Row],[Quantity in Bags]])<=0,"Bags must be greater than 0",IF(N(tFeedPur[[#This Row],[Bag Size in kg]])<=0,"Missing bag size",IF(tFeedPur[[#This Row],[Price per Bag]]="","Missing price",IF(tFeedPur[[#This Row],[Payment Method]]="","Missing payment method","OK"))))))))))
A6: 46204 | B6: ="FP-"&TEXT(ROW()-ROW(tFeedPur[[#Headers],[Date]]),"00000") | C6: Layer Mash | D6: Feed Supplier A (sample) | E6: 20 | F6: 25 | G6: =N(tFeedPur[[#This Row],[Quantity in Bags]])*N(tFeedPur[[#This Row],[Bag Size in kg]]) | H6: 13500 | I6: =N(tFeedPur[[#This Row],[Quantity in Bags]])*N(tFeedPur[[#This Row],[Price per Bag]]) | J6: =IFERROR(tFeedPur[[#This Row],[Total Cost]]/tFeedPur[[#This Row],[Total Quantity in kg]],0) | K6: Transfer | L6: INV-1002 | M6: SAMPLE DATA - delete or replace | N6: =COUNTIF(INDEX(tFeedPur[[Feed Type]],1):tFeedPur[[#This Row],[Feed Type]],tFeedPur[[#This Row],[Feed Type]]) | O6: =MAX(0,IF((ROW()-ROW(tFeedPur[[#Headers],[Date]]))=1,0,SUMIFS(INDEX(tFeedPur[[Total Quantity in kg]],1):INDEX(tFeedPur[[Total Quantity in kg]],(ROW()-ROW(tFeedPur[[#Headers],[Date]]))-1),INDEX(tFeedPur[[Feed Type]],1):INDEX(tFeedPur[[Feed Type]],(ROW()-ROW(tFeedPur[[#Headers],[Date]]))-1),tFeedPur[[#This Row],[Feed Type]]))-SUMIFS(tFeedIss[[Quantity Issued in kg]],tFeedIss[[Feed Type]],tFeedPur[[#This Row],[Feed Type]],tFeedIss[[Date]],"<"&tFeedPur[[#This Row],[Date]])) | P6: =IFERROR((tFeedPur[[#This Row],[Stock Before Purchase kg]]*IF(tFeedPur[[#This Row],[Purchase No. of Type]]=1,0,LOOKUP(2,1/(INDEX(tFeedPur[[Feed Type]],1):INDEX(tFeedPur[[Feed Type]],(ROW()-ROW(tFeedPur[[#Headers],[Date]]))-1)=tFeedPur[[#This Row],[Feed Type]]),INDEX(tFeedPur[[Avg Cost per kg After Purchase]],1):INDEX(tFeedPur[[Avg Cost per kg After Purchase]],(ROW()-ROW(tFeedPur[[#Headers],[Date]]))-1)))+N(tFeedPur[[#This Row],[Total Cost]]))/(tFeedPur[[#This Row],[Stock Before Purchase kg]]+N(tFeedPur[[#This Row],[Total Quantity in kg]])),IF(tFeedPur[[#This Row],[Purchase No. of Type]]=1,0,LOOKUP(2,1/(INDEX(tFeedPur[[Feed Type]],1):INDEX(tFeedPur[[Feed Type]],(ROW()-ROW(tFeedPur[[#Headers],[Date]]))-1)=tFeedPur[[#This Row],[Feed Type]]),INDEX(tFeedPur[[Avg Cost per kg After Purchase]],1):INDEX(tFeedPur[[Avg Cost per kg After Purchase]],(ROW()-ROW(tFeedPur[[#Headers],[Date]]))-1)))) | Q6: =IF(AND(tFeedPur[[#This Row],[Date]]="",tFeedPur[[#This Row],[Feed Type]]="",tFeedPur[[#This Row],[Quantity in Bags]]=""),"",IF(tFeedPur[[#This Row],[Date]]="","Missing date",IF(NOT(ISNUMBER(tFeedPur[[#This Row],[Date]])),"Date is not a valid date",IF(AND((ROW()-ROW(tFeedPur[[#Headers],[Date]]))>1,tFeedPur[[#This Row],[Date]]<INDEX(tFeedPur[[Date]],MAX(1,(ROW()-ROW(tFeedPur[[#Headers],[Date]]))-1))),"Out of date order - insert this row after earlier purchases",IF(tFeedPur[[#This Row],[Feed Type]]="","Missing feed type",IF(COUNTIF(tFeedTypes[[Feed Type]],tFeedPur[[#This Row],[Feed Type]])=0,"Feed type not in LISTS",IF(N(tFeedPur[[#This Row],[Quantity in Bags]])<=0,"Bags must be greater than 0",IF(N(tFeedPur[[#This Row],[Bag Size in kg]])<=0,"Missing bag size",IF(tFeedPur[[#This Row],[Price per Bag]]="","Missing price",IF(tFeedPur[[#This Row],[Payment Method]]="","Missing payment method","OK"))))))))))
A7: 46223 | B7: ="FP-"&TEXT(ROW()-ROW(tFeedPur[[#Headers],[Date]]),"00000") | C7: Finisher | D7: Feed Supplier B (sample) | E7: 12 | F7: 25 | G7: =N(tFeedPur[[#This Row],[Quantity in Bags]])*N(tFeedPur[[#This Row],[Bag Size in kg]]) | H7: 14500 | I7: =N(tFeedPur[[#This Row],[Quantity in Bags]])*N(tFeedPur[[#This Row],[Price per Bag]]) | J7: =IFERROR(tFeedPur[[#This Row],[Total Cost]]/tFeedPur[[#This Row],[Total Quantity in kg]],0) | K7: Cash | L7: RCPT-220 | M7: SAMPLE DATA - delete or replace | N7: =COUNTIF(INDEX(tFeedPur[[Feed Type]],1):tFeedPur[[#This Row],[Feed Type]],tFeedPur[[#This Row],[Feed Type]]) | O7: =MAX(0,IF((ROW()-ROW(tFeedPur[[#Headers],[Date]]))=1,0,SUMIFS(INDEX(tFeedPur[[Total Quantity in kg]],1):INDEX(tFeedPur[[Total Quantity in kg]],(ROW()-ROW(tFeedPur[[#Headers],[Date]]))-1),INDEX(tFeedPur[[Feed Type]],1):INDEX(tFeedPur[[Feed Type]],(ROW()-ROW(tFeedPur[[#Headers],[Date]]))-1),tFeedPur[[#This Row],[Feed Type]]))-SUMIFS(tFeedIss[[Quantity Issued in kg]],tFeedIss[[Feed Type]],tFeedPur[[#This Row],[Feed Type]],tFeedIss[[Date]],"<"&tFeedPur[[#This Row],[Date]])) | P7: =IFERROR((tFeedPur[[#This Row],[Stock Before Purchase kg]]*IF(tFeedPur[[#This Row],[Purchase No. of Type]]=1,0,LOOKUP(2,1/(INDEX(tFeedPur[[Feed Type]],1):INDEX(tFeedPur[[Feed Type]],(ROW()-ROW(tFeedPur[[#Headers],[Date]]))-1)=tFeedPur[[#This Row],[Feed Type]]),INDEX(tFeedPur[[Avg Cost per kg After Purchase]],1):INDEX(tFeedPur[[Avg Cost per kg After Purchase]],(ROW()-ROW(tFeedPur[[#Headers],[Date]]))-1)))+N(tFeedPur[[#This Row],[Total Cost]]))/(tFeedPur[[#This Row],[Stock Before Purchase kg]]+N(tFeedPur[[#This Row],[Total Quantity in kg]])),IF(tFeedPur[[#This Row],[Purchase No. of Type]]=1,0,LOOKUP(2,1/(INDEX(tFeedPur[[Feed Type]],1):INDEX(tFeedPur[[Feed Type]],(ROW()-ROW(tFeedPur[[#Headers],[Date]]))-1)=tFeedPur[[#This Row],[Feed Type]]),INDEX(tFeedPur[[Avg Cost per kg After Purchase]],1):INDEX(tFeedPur[[Avg Cost per kg After Purchase]],(ROW()-ROW(tFeedPur[[#Headers],[Date]]))-1)))) | Q7: =IF(AND(tFeedPur[[#This Row],[Date]]="",tFeedPur[[#This Row],[Feed Type]]="",tFeedPur[[#This Row],[Quantity in Bags]]=""),"",IF(tFeedPur[[#This Row],[Date]]="","Missing date",IF(NOT(ISNUMBER(tFeedPur[[#This Row],[Date]])),"Date is not a valid date",IF(AND((ROW()-ROW(tFeedPur[[#Headers],[Date]]))>1,tFeedPur[[#This Row],[Date]]<INDEX(tFeedPur[[Date]],MAX(1,(ROW()-ROW(tFeedPur[[#Headers],[Date]]))-1))),"Out of date order - insert this row after earlier purchases",IF(tFeedPur[[#This Row],[Feed Type]]="","Missing feed type",IF(COUNTIF(tFeedTypes[[Feed Type]],tFeedPur[[#This Row],[Feed Type]])=0,"Feed type not in LISTS",IF(N(tFeedPur[[#This Row],[Quantity in Bags]])<=0,"Bags must be greater than 0",IF(N(tFeedPur[[#This Row],[Bag Size in kg]])<=0,"Missing bag size",IF(tFeedPur[[#This Row],[Price per Bag]]="","Missing price",IF(tFeedPur[[#This Row],[Payment Method]]="","Missing payment method","OK"))))))))))
A8: 46264 | B8: ="FP-"&TEXT(ROW()-ROW(tFeedPur[[#Headers],[Date]]),"00000") | C8: Starter | D8: Feed Supplier A (sample) | E8: 20 | F8: 25 | G8: =N(tFeedPur[[#This Row],[Quantity in Bags]])*N(tFeedPur[[#This Row],[Bag Size in kg]]) | H8: 15500 | I8: =N(tFeedPur[[#This Row],[Quantity in Bags]])*N(tFeedPur[[#This Row],[Price per Bag]]) | J8: =IFERROR(tFeedPur[[#This Row],[Total Cost]]/tFeedPur[[#This Row],[Total Quantity in kg]],0) | K8: Transfer | L8: INV-1088 | M8: SAMPLE DATA - delete or replace. 20 bags x 25 kg = 500 kg, recorded ONCE then issued to several pens. | N8: =COUNTIF(INDEX(tFeedPur[[Feed Type]],1):tFeedPur[[#This Row],[Feed Type]],tFeedPur[[#This Row],[Feed Type]]) | O8: =MAX(0,IF((ROW()-ROW(tFeedPur[[#Headers],[Date]]))=1,0,SUMIFS(INDEX(tFeedPur[[Total Quantity in kg]],1):INDEX(tFeedPur[[Total Quantity in kg]],(ROW()-ROW(tFeedPur[[#Headers],[Date]]))-1),INDEX(tFeedPur[[Feed Type]],1):INDEX(tFeedPur[[Feed Type]],(ROW()-ROW(tFeedPur[[#Headers],[Date]]))-1),tFeedPur[[#This Row],[Feed Type]]))-SUMIFS(tFeedIss[[Quantity Issued in kg]],tFeedIss[[Feed Type]],tFeedPur[[#This Row],[Feed Type]],tFeedIss[[Date]],"<"&tFeedPur[[#This Row],[Date]])) | P8: =IFERROR((tFeedPur[[#This Row],[Stock Before Purchase kg]]*IF(tFeedPur[[#This Row],[Purchase No. of Type]]=1,0,LOOKUP(2,1/(INDEX(tFeedPur[[Feed Type]],1):INDEX(tFeedPur[[Feed Type]],(ROW()-ROW(tFeedPur[[#Headers],[Date]]))-1)=tFeedPur[[#This Row],[Feed Type]]),INDEX(tFeedPur[[Avg Cost per kg After Purchase]],1):INDEX(tFeedPur[[Avg Cost per kg After Purchase]],(ROW()-ROW(tFeedPur[[#Headers],[Date]]))-1)))+N(tFeedPur[[#This Row],[Total Cost]]))/(tFeedPur[[#This Row],[Stock Before Purchase kg]]+N(tFeedPur[[#This Row],[Total Quantity in kg]])),IF(tFeedPur[[#This Row],[Purchase No. of Type]]=1,0,LOOKUP(2,1/(INDEX(tFeedPur[[Feed Type]],1):INDEX(tFeedPur[[Feed Type]],(ROW()-ROW(tFeedPur[[#Headers],[Date]]))-1)=tFeedPur[[#This Row],[Feed Type]]),INDEX(tFeedPur[[Avg Cost per kg After Purchase]],1):INDEX(tFeedPur[[Avg Cost per kg After Purchase]],(ROW()-ROW(tFeedPur[[#Headers],[Date]]))-1)))) | Q8: =IF(AND(tFeedPur[[#This Row],[Date]]="",tFeedPur[[#This Row],[Feed Type]]="",tFeedPur[[#This Row],[Quantity in Bags]]=""),"",IF(tFeedPur[[#This Row],[Date]]="","Missing date",IF(NOT(ISNUMBER(tFeedPur[[#This Row],[Date]])),"Date is not a valid date",IF(AND((ROW()-ROW(tFeedPur[[#Headers],[Date]]))>1,tFeedPur[[#This Row],[Date]]<INDEX(tFeedPur[[Date]],MAX(1,(ROW()-ROW(tFeedPur[[#Headers],[Date]]))-1))),"Out of date order - insert this row after earlier purchases",IF(tFeedPur[[#This Row],[Feed Type]]="","Missing feed type",IF(COUNTIF(tFeedTypes[[Feed Type]],tFeedPur[[#This Row],[Feed Type]])=0,"Feed type not in LISTS",IF(N(tFeedPur[[#This Row],[Quantity in Bags]])<=0,"Bags must be greater than 0",IF(N(tFeedPur[[#This Row],[Bag Size in kg]])<=0,"Missing bag size",IF(tFeedPur[[#This Row],[Price per Bag]]="","Missing price",IF(tFeedPur[[#This Row],[Payment Method]]="","Missing payment method","OK"))))))))))
A9: 46280 | B9: ="FP-"&TEXT(ROW()-ROW(tFeedPur[[#Headers],[Date]]),"00000") | C9: Starter | D9: Feed Supplier B (sample) | E9: 10 | F9: 25 | G9: =N(tFeedPur[[#This Row],[Quantity in Bags]])*N(tFeedPur[[#This Row],[Bag Size in kg]]) | H9: 16500 | I9: =N(tFeedPur[[#This Row],[Quantity in Bags]])*N(tFeedPur[[#This Row],[Price per Bag]]) | J9: =IFERROR(tFeedPur[[#This Row],[Total Cost]]/tFeedPur[[#This Row],[Total Quantity in kg]],0) | K9: POS | L9: RCPT-301 | M9: SAMPLE DATA - delete or replace | N9: =COUNTIF(INDEX(tFeedPur[[Feed Type]],1):tFeedPur[[#This Row],[Feed Type]],tFeedPur[[#This Row],[Feed Type]]) | O9: =MAX(0,IF((ROW()-ROW(tFeedPur[[#Headers],[Date]]))=1,0,SUMIFS(INDEX(tFeedPur[[Total Quantity in kg]],1):INDEX(tFeedPur[[Total Quantity in kg]],(ROW()-ROW(tFeedPur[[#Headers],[Date]]))-1),INDEX(tFeedPur[[Feed Type]],1):INDEX(tFeedPur[[Feed Type]],(ROW()-ROW(tFeedPur[[#Headers],[Date]]))-1),tFeedPur[[#This Row],[Feed Type]]))-SUMIFS(tFeedIss[[Quantity Issued in kg]],tFeedIss[[Feed Type]],tFeedPur[[#This Row],[Feed Type]],tFeedIss[[Date]],"<"&tFeedPur[[#This Row],[Date]])) | P9: =IFERROR((tFeedPur[[#This Row],[Stock Before Purchase kg]]*IF(tFeedPur[[#This Row],[Purchase No. of Type]]=1,0,LOOKUP(2,1/(INDEX(tFeedPur[[Feed Type]],1):INDEX(tFeedPur[[Feed Type]],(ROW()-ROW(tFeedPur[[#Headers],[Date]]))-1)=tFeedPur[[#This Row],[Feed Type]]),INDEX(tFeedPur[[Avg Cost per kg After Purchase]],1):INDEX(tFeedPur[[Avg Cost per kg After Purchase]],(ROW()-ROW(tFeedPur[[#Headers],[Date]]))-1)))+N(tFeedPur[[#This Row],[Total Cost]]))/(tFeedPur[[#This Row],[Stock Before Purchase kg]]+N(tFeedPur[[#This Row],[Total Quantity in kg]])),IF(tFeedPur[[#This Row],[Purchase No. of Type]]=1,0,LOOKUP(2,1/(INDEX(tFeedPur[[Feed Type]],1):INDEX(tFeedPur[[Feed Type]],(ROW()-ROW(tFeedPur[[#Headers],[Date]]))-1)=tFeedPur[[#This Row],[Feed Type]]),INDEX(tFeedPur[[Avg Cost per kg After Purchase]],1):INDEX(tFeedPur[[Avg Cost per kg After Purchase]],(ROW()-ROW(tFeedPur[[#Headers],[Date]]))-1)))) | Q9: =IF(AND(tFeedPur[[#This Row],[Date]]="",tFeedPur[[#This Row],[Feed Type]]="",tFeedPur[[#This Row],[Quantity in Bags]]=""),"",IF(tFeedPur[[#This Row],[Date]]="","Missing date",IF(NOT(ISNUMBER(tFeedPur[[#This Row],[Date]])),"Date is not a valid date",IF(AND((ROW()-ROW(tFeedPur[[#Headers],[Date]]))>1,tFeedPur[[#This Row],[Date]]<INDEX(tFeedPur[[Date]],MAX(1,(ROW()-ROW(tFeedPur[[#Headers],[Date]]))-1))),"Out of date order - insert this row after earlier purchases",IF(tFeedPur[[#This Row],[Feed Type]]="","Missing feed type",IF(COUNTIF(tFeedTypes[[Feed Type]],tFeedPur[[#This Row],[Feed Type]])=0,"Feed type not in LISTS",IF(N(tFeedPur[[#This Row],[Quantity in Bags]])<=0,"Bags must be greater than 0",IF(N(tFeedPur[[#This Row],[Bag Size in kg]])<=0,"Missing bag size",IF(tFeedPur[[#This Row],[Price per Bag]]="","Missing price",IF(tFeedPur[[#This Row],[Payment Method]]="","Missing payment method","OK"))))))))))
A10: 46280 | B10: ="FP-"&TEXT(ROW()-ROW(tFeedPur[[#Headers],[Date]]),"00000") | C10: Grower | D10: Feed Supplier A (sample) | E10: 20 | F10: 25 | G10: =N(tFeedPur[[#This Row],[Quantity in Bags]])*N(tFeedPur[[#This Row],[Bag Size in kg]]) | H10: 16000 | I10: =N(tFeedPur[[#This Row],[Quantity in Bags]])*N(tFeedPur[[#This Row],[Price per Bag]]) | J10: =IFERROR(tFeedPur[[#This Row],[Total Cost]]/tFeedPur[[#This Row],[Total Quantity in kg]],0) | K10: Credit | L10: INV-1102 | M10: SAMPLE DATA - delete or replace | N10: =COUNTIF(INDEX(tFeedPur[[Feed Type]],1):tFeedPur[[#This Row],[Feed Type]],tFeedPur[[#This Row],[Feed Type]]) | O10: =MAX(0,IF((ROW()-ROW(tFeedPur[[#Headers],[Date]]))=1,0,SUMIFS(INDEX(tFeedPur[[Total Quantity in kg]],1):INDEX(tFeedPur[[Total Quantity in kg]],(ROW()-ROW(tFeedPur[[#Headers],[Date]]))-1),INDEX(tFeedPur[[Feed Type]],1):INDEX(tFeedPur[[Feed Type]],(ROW()-ROW(tFeedPur[[#Headers],[Date]]))-1),tFeedPur[[#This Row],[Feed Type]]))-SUMIFS(tFeedIss[[Quantity Issued in kg]],tFeedIss[[Feed Type]],tFeedPur[[#This Row],[Feed Type]],tFeedIss[[Date]],"<"&tFeedPur[[#This Row],[Date]])) | P10: =IFERROR((tFeedPur[[#This Row],[Stock Before Purchase kg]]*IF(tFeedPur[[#This Row],[Purchase No. of Type]]=1,0,LOOKUP(2,1/(INDEX(tFeedPur[[Feed Type]],1):INDEX(tFeedPur[[Feed Type]],(ROW()-ROW(tFeedPur[[#Headers],[Date]]))-1)=tFeedPur[[#This Row],[Feed Type]]),INDEX(tFeedPur[[Avg Cost per kg After Purchase]],1):INDEX(tFeedPur[[Avg Cost per kg After Purchase]],(ROW()-ROW(tFeedPur[[#Headers],[Date]]))-1)))+N(tFeedPur[[#This Row],[Total Cost]]))/(tFeedPur[[#This Row],[Stock Before Purchase kg]]+N(tFeedPur[[#This Row],[Total Quantity in kg]])),IF(tFeedPur[[#This Row],[Purchase No. of Type]]=1,0,LOOKUP(2,1/(INDEX(tFeedPur[[Feed Type]],1):INDEX(tFeedPur[[Feed Type]],(ROW()-ROW(tFeedPur[[#Headers],[Date]]))-1)=tFeedPur[[#This Row],[Feed Type]]),INDEX(tFeedPur[[Avg Cost per kg After Purchase]],1):INDEX(tFeedPur[[Avg Cost per kg After Purchase]],(ROW()-ROW(tFeedPur[[#Headers],[Date]]))-1)))) | Q10: =IF(AND(tFeedPur[[#This Row],[Date]]="",tFeedPur[[#This Row],[Feed Type]]="",tFeedPur[[#This Row],[Quantity in Bags]]=""),"",IF(tFeedPur[[#This Row],[Date]]="","Missing date",IF(NOT(ISNUMBER(tFeedPur[[#This Row],[Date]])),"Date is not a valid date",IF(AND((ROW()-ROW(tFeedPur[[#Headers],[Date]]))>1,tFeedPur[[#This Row],[Date]]<INDEX(tFeedPur[[Date]],MAX(1,(ROW()-ROW(tFeedPur[[#Headers],[Date]]))-1))),"Out of date order - insert this row after earlier purchases",IF(tFeedPur[[#This Row],[Feed Type]]="","Missing feed type",IF(COUNTIF(tFeedTypes[[Feed Type]],tFeedPur[[#This Row],[Feed Type]])=0,"Feed type not in LISTS",IF(N(tFeedPur[[#This Row],[Quantity in Bags]])<=0,"Bags must be greater than 0",IF(N(tFeedPur[[#This Row],[Bag Size in kg]])<=0,"Missing bag size",IF(tFeedPur[[#This Row],[Price per Bag]]="","Missing price",IF(tFeedPur[[#This Row],[Payment Method]]="","Missing payment method","OK"))))))))))

Sheet FEED_ISSUES
A1: FEED ISSUES
A2: Each time feed leaves the store for a pen, record it here. This reduces inventory and charges the cost (weighted-average) to the pen & batch. Record only what happened.
A3: ■ GREEN header = you enter / select ■ GREY header = automatic (do not type) Add a new record by typing in the first empty row directly under the table.
A4: Date | B4: Issue ID | C4: Feed Type | D4: Pen ID | E4: Batch ID | F4: Quantity Issued in kg | G4: Cost per kg | H4: Total Cost | I4: Issued By | J4: Notes | K4: Animal Type | L4: Store Balance on Date kg | M4: Check
A5: 46205 | B5: ="FI-"&TEXT(ROW()-ROW(tFeedIss[[#Headers],[Date]]),"00000") | C5: Starter | D5: P006 | E5: BROILER-JUL-001 | F5: 150 | G5: =IFERROR(LOOKUP(2,1/((tFeedPur[[Feed Type]]=tFeedIss[[#This Row],[Feed Type]])*(tFeedPur[[Date]]<=tFeedIss[[#This Row],[Date]])),tFeedPur[[Avg Cost per kg After Purchase]]),0) | H5: =N(tFeedIss[[#This Row],[Quantity Issued in kg]])*tFeedIss[[#This Row],[Cost per kg]] | I5: Attendant 1 | J5: SAMPLE DATA - delete or replace | K5: =IFERROR(INDEX(tBatches[[Animal Type]],MATCH(tFeedIss[[#This Row],[Batch ID]],tBatches[[Batch ID]],0)),"") | L5: =SUMIFS(tFeedPur[[Total Quantity in kg]],tFeedPur[[Feed Type]],tFeedIss[[#This Row],[Feed Type]],tFeedPur[[Date]],"<="&tFeedIss[[#This Row],[Date]])-SUMIFS(tFeedIss[[Quantity Issued in kg]],tFeedIss[[Feed Type]],tFeedIss[[#This Row],[Feed Type]],tFeedIss[[Date]],"<="&tFeedIss[[#This Row],[Date]]) | M5: =IF(AND(tFeedIss[[#This Row],[Date]]="",tFeedIss[[#This Row],[Feed Type]]="",tFeedIss[[#This Row],[Pen ID]]="",tFeedIss[[#This Row],[Batch ID]]="",tFeedIss[[#This Row],[Quantity Issued in kg]]=""),"",IF(tFeedIss[[#This Row],[Date]]="","Missing date",IF(NOT(ISNUMBER(tFeedIss[[#This Row],[Date]])),"Date is not a valid date",IF(tFeedIss[[#This Row],[Feed Type]]="","Missing feed type",IF(COUNTIF(tFeedTypes[[Feed Type]],tFeedIss[[#This Row],[Feed Type]])=0,"Feed type not in LISTS",IF(tFeedIss[[#This Row],[Pen ID]]="","Missing Pen ID",IF(COUNTIF(tPens[[Pen ID]],tFeedIss[[#This Row],[Pen ID]])=0,"Pen "&tFeedIss[[#This Row],[Pen ID]]&" is not in PEN_REGISTER",IF(tFeedIss[[#This Row],[Batch ID]]="","Missing Batch ID",IF(COUNTIF(tBatches[[Batch ID]],tFeedIss[[#This Row],[Batch ID]])=0,"Batch "&tFeedIss[[#This Row],[Batch ID]]&" is not in BATCH_REGISTER",IF(COUNTIFS(tBatches[[Batch ID]],tFeedIss[[#This Row],[Batch ID]],tBatches[[Pen ID]],tFeedIss[[#This Row],[Pen ID]])=0,"Batch "&tFeedIss[[#This Row],[Batch ID]]&" belongs to pen "&INDEX(tBatches[[Pen ID]],MATCH(tFeedIss[[#This Row],[Batch ID]],tBatches[[Batch ID]],0)),IF(tFeedIss[[#This Row],[Date]]<INDEX(tBatches[[Batch Start Date]],MATCH(tFeedIss[[#This Row],[Batch ID]],tBatches[[Batch ID]],0)),"Date is before the batch start date",IF(AND(N(INDEX(tBatches[[Closing Date]],MATCH(tFeedIss[[#This Row],[Batch ID]],tBatches[[Batch ID]],0)))>0,tFeedIss[[#This Row],[Date]]>INDEX(tBatches[[Closing Date]],MATCH(tFeedIss[[#This Row],[Batch ID]],tBatches[[Batch ID]],0))),"Date is after the batch closing date",IF(N(tFeedIss[[#This Row],[Quantity Issued in kg]])<=0,"Quantity must be greater than 0",IF(tFeedIss[[#This Row],[Cost per kg]]=0,"No purchase of this feed on/before this date",IF(tFeedIss[[#This Row],[Store Balance on Date kg]]<-0.0001,"EXCEEDS STOCK by "&TEXT(-tFeedIss[[#This Row],[Store Balance on Date kg]],"#,##0.0")&" kg","OK")))))))))))))))
A6: 46223 | B6: ="FI-"&TEXT(ROW()-ROW(tFeedIss[[#Headers],[Date]]),"00000") | C6: Starter | D6: P006 | E6: BROILER-JUL-001 | F6: 150 | G6: =IFERROR(LOOKUP(2,1/((tFeedPur[[Feed Type]]=tFeedIss[[#This Row],[Feed Type]])*(tFeedPur[[Date]]<=tFeedIss[[#This Row],[Date]])),tFeedPur[[Avg Cost per kg After Purchase]]),0) | H6: =N(tFeedIss[[#This Row],[Quantity Issued in kg]])*tFeedIss[[#This Row],[Cost per kg]] | I6: Attendant 1 | J6: SAMPLE DATA - delete or replace | K6: =IFERROR(INDEX(tBatches[[Animal Type]],MATCH(tFeedIss[[#This Row],[Batch ID]],tBatches[[Batch ID]],0)),"") | L6: =SUMIFS(tFeedPur[[Total Quantity in kg]],tFeedPur[[Feed Type]],tFeedIss[[#This Row],[Feed Type]],tFeedPur[[Date]],"<="&tFeedIss[[#This Row],[Date]])-SUMIFS(tFeedIss[[Quantity Issued in kg]],tFeedIss[[Feed Type]],tFeedIss[[#This Row],[Feed Type]],tFeedIss[[Date]],"<="&tFeedIss[[#This Row],[Date]]) | M6: =IF(AND(tFeedIss[[#This Row],[Date]]="",tFeedIss[[#This Row],[Feed Type]]="",tFeedIss[[#This Row],[Pen ID]]="",tFeedIss[[#This Row],[Batch ID]]="",tFeedIss[[#This Row],[Quantity Issued in kg]]=""),"",IF(tFeedIss[[#This Row],[Date]]="","Missing date",IF(NOT(ISNUMBER(tFeedIss[[#This Row],[Date]])),"Date is not a valid date",IF(tFeedIss[[#This Row],[Feed Type]]="","Missing feed type",IF(COUNTIF(tFeedTypes[[Feed Type]],tFeedIss[[#This Row],[Feed Type]])=0,"Feed type not in LISTS",IF(tFeedIss[[#This Row],[Pen ID]]="","Missing Pen ID",IF(COUNTIF(tPens[[Pen ID]],tFeedIss[[#This Row],[Pen ID]])=0,"Pen "&tFeedIss[[#This Row],[Pen ID]]&" is not in PEN_REGISTER",IF(tFeedIss[[#This Row],[Batch ID]]="","Missing Batch ID",IF(COUNTIF(tBatches[[Batch ID]],tFeedIss[[#This Row],[Batch ID]])=0,"Batch "&tFeedIss[[#This Row],[Batch ID]]&" is not in BATCH_REGISTER",IF(COUNTIFS(tBatches[[Batch ID]],tFeedIss[[#This Row],[Batch ID]],tBatches[[Pen ID]],tFeedIss[[#This Row],[Pen ID]])=0,"Batch "&tFeedIss[[#This Row],[Batch ID]]&" belongs to pen "&INDEX(tBatches[[Pen ID]],MATCH(tFeedIss[[#This Row],[Batch ID]],tBatches[[Batch ID]],0)),IF(tFeedIss[[#This Row],[Date]]<INDEX(tBatches[[Batch Start Date]],MATCH(tFeedIss[[#This Row],[Batch ID]],tBatches[[Batch ID]],0)),"Date is before the batch start date",IF(AND(N(INDEX(tBatches[[Closing Date]],MATCH(tFeedIss[[#This Row],[Batch ID]],tBatches[[Batch ID]],0)))>0,tFeedIss[[#This Row],[Date]]>INDEX(tBatches[[Closing Date]],MATCH(tFeedIss[[#This Row],[Batch ID]],tBatches[[Batch ID]],0))),"Date is after the batch closing date",IF(N(tFeedIss[[#This Row],[Quantity Issued in kg]])<=0,"Quantity must be greater than 0",IF(tFeedIss[[#This Row],[Cost per kg]]=0,"No purchase of this feed on/before this date",IF(tFeedIss[[#This Row],[Store Balance on Date kg]]<-0.0001,"EXCEEDS STOCK by "&TEXT(-tFeedIss[[#This Row],[Store Balance on Date kg]],"#,##0.0")&" kg","OK")))))))))))))))
A7: 46228 | B7: ="FI-"&TEXT(ROW()-ROW(tFeedIss[[#Headers],[Date]]),"00000") | C7: Finisher | D7: P006 | E7: BROILER-JUL-001 | F7: 150 | G7: =IFERROR(LOOKUP(2,1/((tFeedPur[[Feed Type]]=tFeedIss[[#This Row],[Feed Type]])*(tFeedPur[[Date]]<=tFeedIss[[#This Row],[Date]])),tFeedPur[[Avg Cost per kg After Purchase]]),0) | H7: =N(tFeedIss[[#This Row],[Quantity Issued in kg]])*tFeedIss[[#This Row],[Cost per kg]] | I7: Attendant 1 | J7: SAMPLE DATA - delete or replace | K7: =IFERROR(INDEX(tBatches[[Animal Type]],MATCH(tFeedIss[[#This Row],[Batch ID]],tBatches[[Batch ID]],0)),"") | L7: =SUMIFS(tFeedPur[[Total Quantity in kg]],tFeedPur[[Feed Type]],tFeedIss[[#This Row],[Feed Type]],tFeedPur[[Date]],"<="&tFeedIss[[#This Row],[Date]])-SUMIFS(tFeedIss[[Quantity Issued in kg]],tFeedIss[[Feed Type]],tFeedIss[[#This Row],[Feed Type]],tFeedIss[[Date]],"<="&tFeedIss[[#This Row],[Date]]) | M7: =IF(AND(tFeedIss[[#This Row],[Date]]="",tFeedIss[[#This Row],[Feed Type]]="",tFeedIss[[#This Row],[Pen ID]]="",tFeedIss[[#This Row],[Batch ID]]="",tFeedIss[[#This Row],[Quantity Issued in kg]]=""),"",IF(tFeedIss[[#This Row],[Date]]="","Missing date",IF(NOT(ISNUMBER(tFeedIss[[#This Row],[Date]])),"Date is not a valid date",IF(tFeedIss[[#This Row],[Feed Type]]="","Missing feed type",IF(COUNTIF(tFeedTypes[[Feed Type]],tFeedIss[[#This Row],[Feed Type]])=0,"Feed type not in LISTS",IF(tFeedIss[[#This Row],[Pen ID]]="","Missing Pen ID",IF(COUNTIF(tPens[[Pen ID]],tFeedIss[[#This Row],[Pen ID]])=0,"Pen "&tFeedIss[[#This Row],[Pen ID]]&" is not in PEN_REGISTER",IF(tFeedIss[[#This Row],[Batch ID]]="","Missing Batch ID",IF(COUNTIF(tBatches[[Batch ID]],tFeedIss[[#This Row],[Batch ID]])=0,"Batch "&tFeedIss[[#This Row],[Batch ID]]&" is not in BATCH_REGISTER",IF(COUNTIFS(tBatches[[Batch ID]],tFeedIss[[#This Row],[Batch ID]],tBatches[[Pen ID]],tFeedIss[[#This Row],[Pen ID]])=0,"Batch "&tFeedIss[[#This Row],[Batch ID]]&" belongs to pen "&INDEX(tBatches[[Pen ID]],MATCH(tFeedIss[[#This Row],[Batch ID]],tBatches[[Batch ID]],0)),IF(tFeedIss[[#This Row],[Date]]<INDEX(tBatches[[Batch Start Date]],MATCH(tFeedIss[[#This Row],[Batch ID]],tBatches[[Batch ID]],0)),"Date is before the batch start date",IF(AND(N(INDEX(tBatches[[Closing Date]],MATCH(tFeedIss[[#This Row],[Batch ID]],tBatches[[Batch ID]],0)))>0,tFeedIss[[#This Row],[Date]]>INDEX(tBatches[[Closing Date]],MATCH(tFeedIss[[#This Row],[Batch ID]],tBatches[[Batch ID]],0))),"Date is after the batch closing date",IF(N(tFeedIss[[#This Row],[Quantity Issued in kg]])<=0,"Quantity must be greater than 0",IF(tFeedIss[[#This Row],[Cost per kg]]=0,"No purchase of this feed on/before this date",IF(tFeedIss[[#This Row],[Store Balance on Date kg]]<-0.0001,"EXCEEDS STOCK by "&TEXT(-tFeedIss[[#This Row],[Store Balance on Date kg]],"#,##0.0")&" kg","OK")))))))))))))))
